Workbook

Sheet LP_NH_NI_NS
A1: Electronics
A2: Electronics | B2: Arcade Equipment
A3: Electronics | B3: Arcade Equipment | C3: Basketball Arcade Games
A4: Electronics | B4: Arcade Equipment | C4: Pinball Machine Accessories
A5: Electronics | B5: Audio
A6: Electronics | B6: Audio | C6: Audio Accessories
A7: Electronics | B7: Audio | C7: Audio Accessories | D7: Karaoke System Accessories
A8: Electronics | B8: Audio | C8: Audio Accessories | D8: Karaoke System Accessories | E8: Karaoke Chips
A9: Electronics | B9: Audio | C9: Audio Accessories | D9: MP3 Player Accessories
A10: Electronics | B10: Audio | C10: Audio Accessories | D10: MP3 Player Accessories | E10: MP3 Player & Mobile Phone Accessory Sets
A11: Electronics | B11: Audio | C11: Audio Accessories | D11: MP3 Player Accessories | E11: MP3 Player Cases
A12: Electronics | B12: Audio | C12: Audio Accessories | D12: Microphone Accessories
A13: Electronics | B13: Audio | C13: Audio Accessories | D13: Speaker Accessories
A14: Electronics | B14: Audio | C14: Audio Accessories | D14: Speaker Accessories | E14: Speaker Bags, Covers & Cases
A15: Electronics | B15: Audio | C15: Audio Accessories | D15: Speaker Accessories | E15: Speaker Components & Kits
A16: Electronics | B16: Audio | C16: Audio Components
A17: Electronics | B17: Audio | C17: Audio Components | D17: Audio & Video Receivers
A18: Electronics | B18: Audio | C18: Audio Components | D18: Audio Amplifiers
A19: Electronics | B19: Audio | C19: Audio Components | D19: Audio Amplifiers | E19: Headphone Amplifiers
A20: Electronics | B20: Audio | C20: Audio Components | D20: Audio Amplifiers | E20: Power Amplifiers
A21: Electronics | B21: Audio | C21: Audio Components | D21: Channel Strips
A22: Electronics | B22: Audio | C22: Audio Components | D22: Headphones & Headsets
A23: Electronics | B23: Audio | C23: Audio Components | D23: Headphones & Headsets | E23: Headphones
A24: Electronics | B24: Audio | C24: Audio Components | D24: Headphones & Headsets | E24: Headsets
A25: Electronics | B25: Audio | C25: Audio Components | D25: Microphones
A26: Electronics | B26: Audio | C26: Audio Components | D26: Signal Processors
A27: Electronics | B27: Audio | C27: Audio Components | D27: Signal Processors | E27: Crossovers
A28: Electronics | B28: Audio | C28: Audio Components | D28: Signal Processors | E28: Effects Processors
A29: Electronics | B29: Audio | C29: Audio Components | D29: Speakers
A30: Electronics | B30: Communications
A31: Electronics | B31: Communications | C31: Answering Machines
A32: Electronics | B32: Communications | C32: Communication Radios
A33: Electronics | B33: Communications | C33: Communication Radios | D33: CB Radios
A34: Electronics | B34: Communications | C34: Communication Radios | D34: Radio Scanners
A35: Electronics | B35: Communications | C35: Intercom Accessories
A36: Electronics | B36: Communications | C36: Telephony
A37: Electronics | B37: Communications | C37: Telephony | D37: Conference Phones
A38: Electronics | B38: Communications | C38: Telephony | D38: Corded Phones
A39: Electronics | B39: Communications | C39: Telephony | D39: Cordless Phones
A40: Electronics | B40: Communications | C40: Telephony | D40: Mobile Phone Accessories
...

Sheet Format
B1: =IF(ISBLANK(LP_NH_NI_NS!A1),"",IF(VLOOKUP(LP_NH_NI_NS!A1,LP_NH_NI_NS!A$1:$G$58,2,FALSE)="","YES","NO")) -> YES | C1: =IF(ISBLANK(LP_NH_NI_NS!B1),"",IF(VLOOKUP(LP_NH_NI_NS!B1,LP_NH_NI_NS!B$1:$G$58,2,FALSE)="","YES","NO")) | D1: =IF(ISBLANK(LP_NH_NI_NS!C1),"",IF(VLOOKUP(LP_NH_NI_NS!C1,LP_NH_NI_NS!C$1:$G$58,2,FALSE)="","YES","NO")) | E1: =IF(ISBLANK(LP_NH_NI_NS!D1),"",IF(VLOOKUP(LP_NH_NI_NS!D1,LP_NH_NI_NS!D$1:$G$58,2,FALSE)="","YES","NO")) | F1: =IF(ISBLANK(LP_NH_NI_NS!E1),"",IF(VLOOKUP(LP_NH_NI_NS!E1,LP_NH_NI_NS!E$1:$G$58,2,FALSE)="","YES","NO")) | G1: =IF(ISBLANK(LP_NH_NI_NS!F1),"",IF(VLOOKUP(LP_NH_NI_NS!F1,LP_NH_NI_NS!F$1:$G$58,2,FALSE)="","YES","NO")) | H1: =IF(ISBLANK(LP_NH_NI_NS!G1),"",IF(VLOOKUP(LP_NH_NI_NS!G1,LP_NH_NI_NS!G$1:$G$58,2,FALSE)="","YES","NO")) | I1: =IF(ISBLANK(LP_NH_NI_NS!H1),"",IF(VLOOKUP(LP_NH_NI_NS!H1,LP_NH_NI_NS!$G$1:H$58,2,FALSE)="","YES","NO")) | J1: =IF(ISBLANK(LP_NH_NI_NS!I1),"",IF(VLOOKUP(LP_NH_NI_NS!I1,LP_NH_NI_NS!$G$1:I$58,2,FALSE)="","YES","NO")) | K1: =IF(ISBLANK(LP_NH_NI_NS!J1),"",IF(VLOOKUP(LP_NH_NI_NS!J1,LP_NH_NI_NS!$G$1:J$58,2,FALSE)="","YES","NO"))
B2: =IF(ISBLANK(LP_NH_NI_NS!A2),"",IF(VLOOKUP(LP_NH_NI_NS!A2,LP_NH_NI_NS!A$1:$G$58,2,FALSE)="","YES","NO")) -> YES | C2: =IF(ISBLANK(LP_NH_NI_NS!B2),"",IF(VLOOKUP(LP_NH_NI_NS!B2,LP_NH_NI_NS!B$1:$G$58,2,FALSE)="","YES","NO")) -> YES | D2: =IF(ISBLANK(LP_NH_NI_NS!C2),"",IF(VLOOKUP(LP_NH_NI_NS!C2,LP_NH_NI_NS!C$1:$G$58,2,FALSE)="","YES","NO")) | E2: =IF(ISBLANK(LP_NH_NI_NS!D2),"",IF(VLOOKUP(LP_NH_NI_NS!D2,LP_NH_NI_NS!D$1:$G$58,2,FALSE)="","YES","NO")) | F2: =IF(ISBLANK(LP_NH_NI_NS!E2),"",IF(VLOOKUP(LP_NH_NI_NS!E2,LP_NH_NI_NS!E$1:$G$58,2,FALSE)="","YES","NO")) | G2: =IF(ISBLANK(LP_NH_NI_NS!F2),"",IF(VLOOKUP(LP_NH_NI_NS!F2,LP_NH_NI_NS!F$1:$G$58,2,FALSE)="","YES","NO"))
B3: =IF(ISBLANK(LP_NH_NI_NS!A3),"",IF(VLOOKUP(LP_NH_NI_NS!A3,LP_NH_NI_NS!A$1:$G$58,2,FALSE)="","YES","NO")) -> YES | C3: =IF(ISBLANK(LP_NH_NI_NS!B3),"",IF(VLOOKUP(LP_NH_NI_NS!B3,LP_NH_NI_NS!B$1:$G$58,2,FALSE)="","YES","NO")) -> YES | D3: =IF(ISBLANK(LP_NH_NI_NS!C3),"",IF(VLOOKUP(LP_NH_NI_NS!C3,LP_NH_NI_NS!C$1:$G$58,2,FALSE)="","YES","NO")) -> YES | E3: =IF(ISBLANK(LP_NH_NI_NS!D3),"",IF(VLOOKUP(LP_NH_NI_NS!D3,LP_NH_NI_NS!D$1:$G$58,2,FALSE)="","YES","NO")) | F3: =IF(ISBLANK(LP_NH_NI_NS!E3),"",IF(VLOOKUP(LP_NH_NI_NS!E3,LP_NH_NI_NS!E$1:$G$58,2,FALSE)="","YES","NO")) | G3: =IF(ISBLANK(LP_NH_NI_NS!F3),"",IF(VLOOKUP(LP_NH_NI_NS!F3,LP_NH_NI_NS!F$1:$G$58,2,FALSE)="","YES","NO"))
B4: =IF(ISBLANK(LP_NH_NI_NS!A4),"",IF(VLOOKUP(LP_NH_NI_NS!A4,LP_NH_NI_NS!A$1:$G$58,2,FALSE)="","YES","NO")) -> YES | C4: =IF(ISBLANK(LP_NH_NI_NS!B4),"",IF(VLOOKUP(LP_NH_NI_NS!B4,LP_NH_NI_NS!B$1:$G$58,2,FALSE)="","YES","NO")) -> YES | D4: =IF(ISBLANK(LP_NH_NI_NS!C4),"",IF(VLOOKUP(LP_NH_NI_NS!C4,LP_NH_NI_NS!C$1:$G$58,2,FALSE)="","YES","NO")) -> YES | E4: =IF(ISBLANK(LP_NH_NI_NS!D4),"",IF(VLOOKUP(LP_NH_NI_NS!D4,LP_NH_NI_NS!D$1:$G$58,2,FALSE)="","YES","NO")) | F4: =IF(ISBLANK(LP_NH_NI_NS!E4),"",IF(VLOOKUP(LP_NH_NI_NS!E4,LP_NH_NI_NS!E$1:$G$58,2,FALSE)="","YES","NO")) | G4: =IF(ISBLANK(LP_NH_NI_NS!F4),"",IF(VLOOKUP(LP_NH_NI_NS!F4,LP_NH_NI_NS!F$1:$G$58,2,FALSE)="","YES","NO"))
B5: =IF(ISBLANK(LP_NH_NI_NS!A5),"",IF(VLOOKUP(LP_NH_NI_NS!A5,LP_NH_NI_NS!A$1:$G$58,2,FALSE)="","YES","NO")) -> YES | C5: =IF(ISBLANK(LP_NH_NI_NS!B5),"",IF(VLOOKUP(LP_NH_NI_NS!B5,LP_NH_NI_NS!B$1:$G$58,2,FALSE)="","YES","NO")) -> YES | D5: =IF(ISBLANK(LP_NH_NI_NS!C5),"",IF(VLOOKUP(LP_NH_NI_NS!C5,LP_NH_NI_NS!C$1:$G$58,2,FALSE)="","YES","NO")) | E5: =IF(ISBLANK(LP_NH_NI_NS!D5),"",IF(VLOOKUP(LP_NH_NI_NS!D5,LP_NH_NI_NS!D$1:$G$58,2,FALSE)="","YES","NO")) | F5: =IF(ISBLANK(LP_NH_NI_NS!E5),"",IF(VLOOKUP(LP_NH_NI_NS!E5,LP_NH_NI_NS!E$1:$G$58,2,FALSE)="","YES","NO")) | G5: =IF(ISBLANK(LP_NH_NI_NS!F5),"",IF(VLOOKUP(LP_NH_NI_NS!F5,LP_NH_NI_NS!F$1:$G$58,2,FALSE)="","YES","NO"))
B6: =IF(ISBLANK(LP_NH_NI_NS!A6),"",IF(VLOOKUP(LP_NH_NI_NS!A6,LP_NH_NI_NS!A$1:$G$58,2,FALSE)="","YES","NO")) -> YES | C6: =IF(ISBLANK(LP_NH_NI_NS!B6),"",IF(VLOOKUP(LP_NH_NI_NS!B6,LP_NH_NI_NS!B$1:$G$58,2,FALSE)="","YES","NO")) -> YES | D6: =IF(ISBLANK(LP_NH_NI_NS!C6),"",IF(VLOOKUP(LP_NH_NI_NS!C6,LP_NH_NI_NS!C$1:$G$58,2,FALSE)="","YES","NO")) -> YES | E6: =IF(ISBLANK(LP_NH_NI_NS!D6),"",IF(VLOOKUP(LP_NH_NI_NS!D6,LP_NH_NI_NS!D$1:$G$58,2,FALSE)="","YES","NO")) | F6: =IF(ISBLANK(LP_NH_NI_NS!E6),"",IF(VLOOKUP(LP_NH_NI_NS!E6,LP_NH_NI_NS!E$1:$G$58,2,FALSE)="","YES","NO")) | G6: =IF(ISBLANK(LP_NH_NI_NS!F6),"",IF(VLOOKUP(LP_NH_NI_NS!F6,LP_NH_NI_NS!F$1:$G$58,2,FALSE)="","YES","NO"))
B7: =IF(ISBLANK(LP_NH_NI_NS!A7),"",IF(VLOOKUP(LP_NH_NI_NS!A7,LP_NH_NI_NS!A$1:$G$58,2,FALSE)="","YES","NO")) -> YES | C7: =IF(ISBLANK(LP_NH_NI_NS!B7),"",IF(VLOOKUP(LP_NH_NI_NS!B7,LP_NH_NI_NS!B$1:$G$58,2,FALSE)="","YES","NO")) -> YES | D7: =IF(ISBLANK(LP_NH_NI_NS!C7),"",IF(VLOOKUP(LP_NH_NI_NS!C7,LP_NH_NI_NS!C$1:$G$58,2,FALSE)="","YES","NO")) -> YES | E7: =IF(ISBLANK(LP_NH_NI_NS!D7),"",IF(VLOOKUP(LP_NH_NI_NS!D7,LP_NH_NI_NS!D$1:$G$58,2,FALSE)="","YES","NO")) -> YES | F7: =IF(ISBLANK(LP_NH_NI_NS!E7),"",IF(VLOOKUP(LP_NH_NI_NS!E7,LP_NH_NI_NS!E$1:$G$58,2,FALSE)="","YES","NO")) | G7: =IF(ISBLANK(LP_NH_NI_NS!F7),"",IF(VLOOKUP(LP_NH_NI_NS!F7,LP_NH_NI_NS!F$1:$G$58,2,FALSE)="","YES","NO"))
B8: =IF(ISBLANK(LP_NH_NI_NS!A8),"",IF(VLOOKUP(LP_NH_NI_NS!A8,LP_NH_NI_NS!A$1:$G$58,2,FALSE)="","YES","NO")) -> YES | C8: =IF(ISBLANK(LP_NH_NI_NS!B8),"",IF(VLOOKUP(LP_NH_NI_NS!B8,LP_NH_NI_NS!B$1:$G$58,2,FALSE)="","YES","NO")) -> YES | D8: =IF(ISBLANK(LP_NH_NI_NS!C8),"",IF(VLOOKUP(LP_NH_NI_NS!C8,LP_NH_NI_NS!C$1:$G$58,2,FALSE)="","YES","NO")) -> YES | E8: =IF(ISBLANK(LP_NH_NI_NS!D8),"",IF(VLOOKUP(LP_NH_NI_NS!D8,LP_NH_NI_NS!D$1:$G$58,2,FALSE)="","YES","NO")) -> YES | F8: =IF(ISBLANK(LP_NH_NI_NS!E8),"",IF(VLOOKUP(LP_NH_NI_NS!E8,LP_NH_NI_NS!E$1:$G$58,2,FALSE)="","YES","NO")) -> YES | G8: =IF(ISBLANK(LP_NH_NI_NS!F8),"",IF(VLOOKUP(LP_NH_NI_NS!F8,LP_NH_NI_NS!F$1:$G$58,2,FALSE)="","YES","NO"))
B9: =IF(ISBLANK(LP_NH_NI_NS!A9),"",IF(VLOOKUP(LP_NH_NI_NS!A9,LP_NH_NI_NS!A$1:$G$58,2,FALSE)="","YES","NO")) -> YES | C9: =IF(ISBLANK(LP_NH_NI_NS!B9),"",IF(VLOOKUP(LP_NH_NI_NS!B9,LP_NH_NI_NS!B$1:$G$58,2,FALSE)="","YES","NO")) -> YES | D9: =IF(ISBLANK(LP_NH_NI_NS!C9),"",IF(VLOOKUP(LP_NH_NI_NS!C9,LP_NH_NI_NS!C$1:$G$58,2,FALSE)="","YES","NO")) -> YES | E9: =IF(ISBLANK(LP_NH_NI_NS!D9),"",IF(VLOOKUP(LP_NH_NI_NS!D9,LP_NH_NI_NS!D$1:$G$58,2,FALSE)="","YES","NO")) -> YES | F9: =IF(ISBLANK(LP_NH_NI_NS!E9),"",IF(VLOOKUP(LP_NH_NI_NS!E9,LP_NH_NI_NS!E$1:$G$58,2,FALSE)="","YES","NO")) | G9: =IF(ISBLANK(LP_NH_NI_NS!F9),"",IF(VLOOKUP(LP_NH_NI_NS!F9,LP_NH_NI_NS!F$1:$G$58,2,FALSE)="","YES","NO"))
B10: =IF(ISBLANK(LP_NH_NI_NS!A10),"",IF(VLOOKUP(LP_NH_NI_NS!A10,LP_NH_NI_NS!A$1:$G$58,2,FALSE)="","YES","NO")) -> YES | C10: =IF(ISBLANK(LP_NH_NI_NS!B10),"",IF(VLOOKUP(LP_NH_NI_NS!B10,LP_NH_NI_NS!B$1:$G$58,2,FALSE)="","YES","NO")) -> YES | D10: =IF(ISBLANK(LP_NH_NI_NS!C10),"",IF(VLOOKUP(LP_NH_NI_NS!C10,LP_NH_NI_NS!C$1:$G$58,2,FALSE)="","YES","NO")) -> YES | E10: =IF(ISBLANK(LP_NH_NI_NS!D10),"",IF(VLOOKUP(LP_NH_NI_NS!D10,LP_NH_NI_NS!D$1:$G$58,2,FALSE)="","YES","NO")) -> YES | F10: =IF(ISBLANK(LP_NH_NI_NS!E10),"",IF(VLOOKUP(LP_NH_NI_NS!E10,LP_NH_NI_NS!E$1:$G$58,2,FALSE)="","YES","NO")) -> YES | G10: =IF(ISBLANK(LP_NH_NI_NS!F10),"",IF(VLOOKUP(LP_NH_NI_NS!F10,LP_NH_NI_NS!F$1:$G$58,2,FALSE)="","YES","NO"))
B11: =IF(ISBLANK(LP_NH_NI_NS!A11),"",IF(VLOOKUP(LP_NH_NI_NS!A11,LP_NH_NI_NS!A$1:$G$58,2,FALSE)="","YES","NO")) -> YES | C11: =IF(ISBLANK(LP_NH_NI_NS!B11),"",IF(VLOOKUP(LP_NH_NI_NS!B11,LP_NH_NI_NS!B$1:$G$58,2,FALSE)="","YES","NO")) -> YES | D11: =IF(ISBLANK(LP_NH_NI_NS!C11),"",IF(VLOOKUP(LP_NH_NI_NS!C11,LP_NH_NI_NS!C$1:$G$58,2,FALSE)="","YES","NO")) -> YES | E11: =IF(ISBLANK(LP_NH_NI_NS!D11),"",IF(VLOOKUP(LP_NH_NI_NS!D11,LP_NH_NI_NS!D$1:$G$58,2,FALSE)="","YES","NO")) -> YES | F11: =IF(ISBLANK(LP_NH_NI_NS!E11),"",IF(VLOOKUP(LP_NH_NI_NS!E11,LP_NH_NI_NS!E$1:$G$58,2,FALSE)="","YES","NO")) -> YES | G11: =IF(ISBLANK(LP_NH_NI_NS!F11),"",IF(VLOOKUP(LP_NH_NI_NS!F11,LP_NH_NI_NS!F$1:$G$58,2,FALSE)="","YES","NO"))
B12: =IF(ISBLANK(LP_NH_NI_NS!A12),"",IF(VLOOKUP(LP_NH_NI_NS!A12,LP_NH_NI_NS!A$1:$G$58,2,FALSE)="","YES","NO")) -> YES | C12: =IF(ISBLANK(LP_NH_NI_NS!B12),"",IF(VLOOKUP(LP_NH_NI_NS!B12,LP_NH_NI_NS!B$1:$G$58,2,FALSE)="","YES","NO")) -> YES | D12: =IF(ISBLANK(LP_NH_NI_NS!C12),"",IF(VLOOKUP(LP_NH_NI_NS!C12,LP_NH_NI_NS!C$1:$G$58,2,FALSE)="","YES","NO")) -> YES | E12: =IF(ISBLANK(LP_NH_NI_NS!D12),"",IF(VLOOKUP(LP_NH_NI_NS!D12,LP_NH_NI_NS!D$1:$G$58,2,FALSE)="","YES","NO")) -> YES | F12: =IF(ISBLANK(LP_NH_NI_NS!E12),"",IF(VLOOKUP(LP_NH_NI_NS!E12,LP_NH_NI_NS!E$1:$G$58,2,FALSE)="","YES","NO")) | G12: =IF(ISBLANK(LP_NH_NI_NS!F12),"",IF(VLOOKUP(LP_NH_NI_NS!F12,LP_NH_NI_NS!F$1:$G$58,2,FALSE)="","YES","NO"))
B13: =IF(ISBLANK(LP_NH_NI_NS!A13),"",IF(VLOOKUP(LP_NH_NI_NS!A13,LP_NH_NI_NS!A$1:$G$58,2,FALSE)="","YES","NO")) -> YES | C13: =IF(ISBLANK(LP_NH_NI_NS!B13),"",IF(VLOOKUP(LP_NH_NI_NS!B13,LP_NH_NI_NS!B$1:$G$58,2,FALSE)="","YES","NO")) -> YES | D13: =IF(ISBLANK(LP_NH_NI_NS!C13),"",IF(VLOOKUP(LP_NH_NI_NS!C13,LP_NH_NI_NS!C$1:$G$58,2,FALSE)="","YES","NO")) -> YES | E13: =IF(ISBLANK(LP_NH_NI_NS!D13),"",IF(VLOOKUP(LP_NH_NI_NS!D13,LP_NH_NI_NS!D$1:$G$58,2,FALSE)="","YES","NO")) -> YES | F13: =IF(ISBLANK(LP_NH_NI_NS!E13),"",IF(VLOOKUP(LP_NH_NI_NS!E13,LP_NH_NI_NS!E$1:$G$58,2,FALSE)="","YES","NO")) | G13: =IF(ISBLANK(LP_NH_NI_NS!F13),"",IF(VLOOKUP(LP_NH_NI_NS!F13,LP_NH_NI_NS!F$1:$G$58,2,FALSE)="","YES","NO"))
... B51: =IF(ISBLANK(LP_NH_NI_NS!A51),"",IF(VLOOKUP(LP_NH_NI_NS!A51,LP_NH_NI_NS!A$1:$G$58,2,FALSE)="","YES","NO")) -> YES | C51: =IF(ISBLANK(LP_NH_NI_NS!B51),"",IF(VLOOKUP(LP_NH_NI_NS!B51,LP_NH_NI_NS!B$1:$G$58,2,FALSE)="","YES","NO")) -> YES | D51: =IF(ISBLANK(LP_NH_NI_NS!C51),"",IF(VLOOKUP(LP_NH_NI_NS!C51,LP_NH_NI_NS!C$1:$G$58,2,FALSE)="","YES","NO")) -> YES | E51: =IF(ISBLANK(LP_NH_NI_NS!D51),"",IF(VLOOKUP(LP_NH_NI_NS!D51,LP_NH_NI_NS!D$1:$G$58,2,FALSE)="","YES","NO")) -> YES | F51: =IF(ISBLANK(LP_NH_NI_NS!E51),"",IF(VLOOKUP(LP_NH_NI_NS!E51,LP_NH_NI_NS!E$1:$G$58,2,FALSE)="","YES","NO")) | G51: =IF(ISBLANK(LP_NH_NI_NS!F51),"",IF(VLOOKUP(LP_NH_NI_NS!F51,LP_NH_NI_NS!F$1:$G$58,2,FALSE)="","YES","NO"))
B52: =IF(ISBLANK(LP_NH_NI_NS!A55),"",IF(VLOOKUP(LP_NH_NI_NS!A55,LP_NH_NI_NS!A$1:$G$58,2,FALSE)="","YES","NO")) -> YES | C52: =IF(ISBLANK(LP_NH_NI_NS!B55),"",IF(VLOOKUP(LP_NH_NI_NS!B55,LP_NH_NI_NS!B$1:$G$58,2,FALSE)="","YES","NO")) -> YES | D52: =IF(ISBLANK(LP_NH_NI_NS!C55),"",IF(VLOOKUP(LP_NH_NI_NS!C55,LP_NH_NI_NS!C$1:$G$58,2,FALSE)="","YES","NO")) -> YES | E52: =IF(ISBLANK(LP_NH_NI_NS!D55),"",IF(VLOOKUP(LP_NH_NI_NS!D55,LP_NH_NI_NS!D$1:$G$58,2,FALSE)="","YES","NO")) -> YES | F52: =IF(ISBLANK(LP_NH_NI_NS!E55),"",IF(VLOOKUP(LP_NH_NI_NS!E55,LP_NH_NI_NS!E$1:$G$58,2,FALSE)="","YES","NO")) -> YES | G52: =IF(ISBLANK(LP_NH_NI_NS!F55),"",IF(VLOOKUP(LP_NH_NI_NS!F55,LP_NH_NI_NS!F$1:$G$58,2,FALSE)="","YES","NO"))
B53: =IF(ISBLANK(LP_NH_NI_NS!A56),"",IF(VLOOKUP(LP_NH_NI_NS!A56,LP_NH_NI_NS!A$1:$G$58,2,FALSE)="","YES","NO")) -> YES | C53: =IF(ISBLANK(LP_NH_NI_NS!B56),"",IF(VLOOKUP(LP_NH_NI_NS!B56,LP_NH_NI_NS!B$1:$G$58,2,FALSE)="","YES","NO")) -> YES | D53: =IF(ISBLANK(LP_NH_NI_NS!C56),"",IF(VLOOKUP(LP_NH_NI_NS!C56,LP_NH_NI_NS!C$1:$G$58,2,FALSE)="","YES","NO")) -> YES | E53: =IF(ISBLANK(LP_NH_NI_NS!D56),"",IF(VLOOKUP(LP_NH_NI_NS!D56,LP_NH_NI_NS!D$1:$G$58,2,FALSE)="","YES","NO")) -> YES | F53: =IF(ISBLANK(LP_NH_NI_NS!E56),"",IF(VLOOKUP(LP_NH_NI_NS!E56,LP_NH_NI_NS!E$1:$G$58,2,FALSE)="","YES","NO")) -> YES | G53: =IF(ISBLANK(LP_NH_NI_NS!F56),"",IF(VLOOKUP(LP_NH_NI_NS!F56,LP_NH_NI_NS!F$1:$G$58,2,FALSE)="","YES","NO"))
B54: =IF(ISBLANK(LP_NH_NI_NS!A57),"",IF(VLOOKUP(LP_NH_NI_NS!A57,LP_NH_NI_NS!A$1:$G$58,2,FALSE)="","YES","NO")) -> YES | C54: =IF(ISBLANK(LP_NH_NI_NS!B57),"",IF(VLOOKUP(LP_NH_NI_NS!B57,LP_NH_NI_NS!B$1:$G$58,2,FALSE)="","YES","NO")) -> YES | D54: =IF(ISBLANK(LP_NH_NI_NS!C57),"",IF(VLOOKUP(LP_NH_NI_NS!C57,LP_NH_NI_NS!C$1:$G$58,2,FALSE)="","YES","NO")) -> YES | E54: =IF(ISBLANK(LP_NH_NI_NS!D57),"",IF(VLOOKUP(LP_NH_NI_NS!D57,LP_NH_NI_NS!D$1:$G$58,2,FALSE)="","YES","NO")) -> YES | F54: =IF(ISBLANK(LP_NH_NI_NS!E57),"",IF(VLOOKUP(LP_NH_NI_NS!E57,LP_NH_NI_NS!E$1:$G$58,2,FALSE)="","YES","NO")) -> YES | G54: =IF(ISBLANK(LP_NH_NI_NS!F57),"",IF(VLOOKUP(LP_NH_NI_NS!F57,LP_NH_NI_NS!F$1:$G$58,2,FALSE)="","YES","NO")) -> YES
B55: =IF(ISBLANK(LP_NH_NI_NS!A58),"",IF(VLOOKUP(LP_NH_NI_NS!A58,LP_NH_NI_NS!A$1:$G$58,2,FALSE)="","YES","NO")) -> YES | C55: =IF(ISBLANK(LP_NH_NI_NS!B58),"",IF(VLOOKUP(LP_NH_NI_NS!B58,LP_NH_NI_NS!B$1:$G$58,2,FALSE)="","YES","NO")) -> YES | D55: =IF(ISBLANK(LP_NH_NI_NS!C58),"",IF(VLOOKUP(LP_NH_NI_NS!C58,LP_NH_NI_NS!C$1:$G$58,2,FALSE)="","YES","NO")) -> YES | E55: =IF(ISBLANK(LP_NH_NI_NS!D58),"",IF(VLOOKUP(LP_NH_NI_NS!D58,LP_NH_NI_NS!D$1:$G$58,2,FALSE)="","YES","NO")) -> YES | F55: =IF(ISBLANK(LP_NH_NI_NS!E58),"",IF(VLOOKUP(LP_NH_NI_NS!E58,LP_NH_NI_NS!E$1:$G$58,2,FALSE)="","YES","NO")) -> YES | G55: =IF(ISBLANK(LP_NH_NI_NS!F58),"",IF(VLOOKUP(LP_NH_NI_NS!F58,LP_NH_NI_NS!F$1:$G$58,2,FALSE)="","YES","NO")) -> YES
